Workbook

Sheet FL1-4 SS op sheet
D1: early='29-'35; mid='35-'45, late='45-'54
B5: 16793.393 ft | D5: tib_FEED_SS_IM2_TAB_2031-01 - FLOW_FL-1 @ 86400 s | F5: 16534.99 ft | H5: tib_FEED_SS_IM2_TAB_2031-01 - FLOW_FL-2 @ 86400 s | N5: 9183.98 ft | P5: tib_FEED_SS_IM2_TAB_2031-01 - FLOW_FL-3 @ 86400 s
D6: 238.39142 | H6: 238.3871 | P6: 226.86854
D7: 205.56305 | H7: 205.81019 | P7: 218.51258
B10: 16793.393 | D10: tib_FEED_SS_IM2_TAB_2031-09 - FLOW_FL-1 @ 86400 s | F10: 16534.994 | H10: tib_FEED_SS_IM2_TAB_2031-09 - FLOW_FL-2 @ 86400 s | N10: 9183.98 | P10: tib_FEED_SS_IM2_TAB_2031-09 - FLOW_FL-3 @ 86400 s
D11: 216.96044 | H11: 216.95756 | P11: 201.21953
D12: 187.43601 | H12: 187.65098 | P12: 195.04405
B15: 16793.393 | D15: tib_FEED_SS_IM2_TAB_2031-12 - FLOW_FL-1 @ 86400 s | F15: 16534.994 | H15: tib_FEED_SS_IM2_TAB_2031-12 - FLOW_FL-2 @ 86400 s | N15: 9183.98 | P15: tib_FEED_SS_IM2_TAB_2031-12 - FLOW_FL-3 @ 86400 s
D16: 212.88722 | H16: 212.8847 | P16: 196.58644
D17: 184.12126 | H17: 184.32102 | P17: 190.61854
B20: 16793.393 | D20: tib_FEED_SS_IM2_TAB_2035-03 - FLOW_FL-1 @ 86400 s | F20: 16534.994 | H20: tib_FEED_SS_IM2_TAB_2035-03 - FLOW_FL-2 @ 86400 s | N20: 9183.98 | P20: tib_FEED_SS_IM2_TAB_2035-03 - FLOW_FL-3 @ 86400 s
D21: 191.36608 | H21: 191.36181 | P21: 163.53736
D22: 159.80043 | H22: 160.07421 | P22: 155.15594
B25: 16534.994 | D25: tib_FEED_SS_IM3_TAB_2030-09_1R_woSSP - FLOW_FL-2 @ 86400 s | F25: 16534.994 | H25: tib_FEED_SS_IM3_TAB_2030-09_1R_woSSP - FLOW_FL-2 @ 86400 s | N25: 9108.5223 | P25: tib_FEED_SS_IM3_TAB_2030-09_1R_woSSP - FLOW_FL-4 @ 86400 s
D26: 204.97598 | H26: 204.97598 | P26: 215.78486
D27: 171.97468 | H27: 171.97468 | P27: 199.04959
B30: 16534.994 | D30: tib_FEED_SS_IM3_TAB_2040-12_1R - FLOW_FL-2 @ 86400 s | F30: 16534.994 | H30: tib_FEED_SS_IM3_TAB_2040-12_1R - FLOW_FL-2 @ 86400 s | N30: 9108.5223 | P30: tib_FEED_SS_IM3_TAB_2040-12_1R - FLOW_FL-4 @ 86400 s
D31: 187.18635 | H31: 187.18635 | P31: 133.33931
D32: 158.98208 | H32: 158.98208 | P32: 125.23741
B35: 16534.994 | D35: tib_FEED_SS_IM3_TAB_2045-11_1R - FLOW_FL-2 @ 86400 s | F35: 16534.994 | H35: tib_FEED_SS_IM3_TAB_2045-11_1R - FLOW_FL-2 @ 86400 s | N35: 9108.5223 | P35: tib_FEED_SS_IM3_TAB_2045-11_1R - FLOW_FL-4 @ 86400 s
D36: 185.75117 | H36: 185.75117 | P36: 123.2694
D37: 155.66655 | H37: 155.66655 | P37: 114.69027

Sheet FL1-4 SS pcl sheet
D5: tib_FEED_SD_IM2_TAB_2031-01 - FLOW_FL-1 @ 6 h | L5: tib_FEED_SD_IM2_TAB_2031-01 - FLOW_FL-2 @ 6 h | T5: tib_FEED_SD_IM2_TAB_2031-01 - FLOW_FL-3 @ 6 h
F6: 16793.393 | H6: 169.07389 | N6: 16534.994 | P6: 168.71407 | V6: 9183.98 | X6: 180.95596
H7: 101.27518 | P7: 89.851927 | X7: 163.87561
D11: tib_FEED_SD_IM2_TAB_2035-03 - FLOW_FL-1 @ 6 h | L11: tib_FEED_SD_IM2_TAB_2035-03 - FLOW_FL-2 @ 6 h | T11: tib_FEED_SD_IM2_TAB_2035-03 - FLOW_FL-3 @ 6 h
F12: 16793.393 | H12: 138.5211 | N12: 16534.994 | P12: 138.27569 | V12: 9183.98 | X12: 133.30452
H13: 89.731939 | P13: 93.500275 | X13: 122.49408
L17: tib_FEED_SD_IM3_TAB_2045-11_1R - FLOW_FL-2 @ 6 h | T17: tib_FEED_SD_IM3_TAB_2045-11_1R - FLOW_FL-4 @ 6 h
N18: 16534.994 | P18: 138.10543 | V18: 9108.5223 | X18: 101.93146
P19: 92.734951 | X19: 95.091907

Sheet FL6 data
C1: steady state operating | U1: PCL (6h) | AK1: HCL (12h) | BG1: FCD (120hh)
C2: tib_FEED_SS_IM4_TAB_2030_06_48h - FLOW-FL-5-TB @ 86400 s | I2: tib_FEED_SS_IM4_TAB_2036_01_48h - FLOW-FL-5-TB @ 86400 s | O2: tib_FEED_SS_IM4_TAB_2045_09_120h - FLOW-FL-5-TB @ 432000 s | U2: tib_FEED_SD_IM4_TAB_2030_06 - FLOW-FL-5-TB @ 6 h | Z2: tib_FEED_SD_IM4_TAB_2036_01 - FLOW-FL-5-TB @ 6 h | AE2: tib_FEED_SD_IM4_TAB_2045_09 - FLOW-FL-5-TB @ 6 h | AK2: tib_FEED_SD_IM4_TAB_2030_06 - FLOW-FL-5-TB @ 12 h | AR2: tib_FEED_SD_IM4_TAB_2036_01 - FLOW-FL-5-TB @ 12 h | AY2: tib_FEED_SD_IM4_TAB_2045_09 - FLOW-FL-5-TB @ 12 h | BG2: CASE | BH2: G-2_50pcJT_PSD | BJ2: CASE | BK2: G-1_50pcJT_PSD | BM2: CASE | BN2: G-2_50pcJT_PSD | BQ2: CASE | BR2: G-1_50pcJT_PSD
BG3: BRANCH | BH3: FLOW-FL-6-TB | BJ3: BRANCH | BK3: FLOW-FL-6-TB | BM3: BRANCH | BN3: FLOW-FL-6-TB | BQ3: BRANCH | BR3: FLOW-FL-6-TB
D4: Fluid temperature | E4: Pressure | F4: Fluid mixture density including all phases (also any solids, drilling fluids and deposits) in all layers. | G4: . | J4: Fluid temperature | K4: Pressure | L4: Fluid mixture density including all phases (also any solids, drilling fluids and deposits) in all layers. | M4: . | P4: Fluid temperature | Q4: Pressure | R4: Fluid mixture density including all phases (also any solids, drilling fluids and deposits) in all layers. | S4: . | V4: Fluid temperature | W4: Pressure | X4: Fluid mixture density including all phases (also any solids, drilling fluids and deposits) in all layers. | Y4: . | AA4: Fluid temperature | AB4: Pressure | AC4: Fluid mixture density including all phases (also any solids, drilling fluids and deposits) in all layers. | AD4: . | AF4: Fluid temperature | AG4: Pressure | AH4: Fluid mixture density including all phases (also any solids, drilling fluids and deposits) in all layers. | AI4: . | AL4: Fluid temperature | AN4: Pressure | AP4: Fluid mixture density including all phases (also any solids, drilling fluids and deposits) in all layers. | AQ4: . | AS4: Fluid temperature | AU4: Pressure | AW4: Fluid mixture density including all phases (also any solids, drilling fluids and deposits) in all layers. | AX4: . | AZ4: Fluid temperature | BB4: Pressure | BD4: Fluid mixture density including all phases (also any solids, drilling fluids and deposits) in all layers. | BE4: . | BG4: VARIABLE | BH4: PT | BJ4: VARIABLE | BK4: PT | BM4: VARIABLE | BN4: TM | BQ4: VARIABLE | BR4: TM
B5: Distance [mi] | C5: Distance [mi] | D5: Temperature [Â°F] | E5: Pressure [psia] | F5: Density [lb/ftÂ³] | G5: . | H5: Distance [mi] | I5: Distance [mi] | J5: Temperature [Â°F] | K5: Pressure [psia] | L5: Density [lb/ftÂ³] | M5: . | N5: Distance [mi] | O5: Distance [mi] | P5: Temperature [Â°F] | Q5: Pressure [psia] | R5: Density [lb/ftÂ³] | S5: . | U5: Distance [ft] | V5: Temperature [Â°F] | W5: Pressure [psia] | X5: Density [lb/ftÂ³] | Y5: . | Z5: Distance [ft] | AA5: Temperature [Â°F] | AB5: Pressure [psia] | AC5: Density [lb/ftÂ³] | AD5: . | AE5: Distance [ft] | AF5: Temperature [Â°F] | AG5: Pressure [psia] | AH5: Density [lb/ftÂ³] | AI5: . | AK5: Distance [ft] | AL5: Temperature [Â°F] | AM5: Distance [ft] | AN5: Pressure [psia] | AO5: Distance [ft] | AP5: Density [lb/ftÂ³] | AQ5: . | AR5: Distance [ft] | AS5: Temperature [Â°F] | AT5: Distance [ft] | AU5: Pressure [psia] | AV5: Distance [ft] | AW5: Density [lb/ftÂ³] | AX5: . | AY5: Distance [ft] | AZ5: Temperature [Â°F] | BA5: Distance [ft] | BB5: Pressure [psia] | BC5: Distance [ft] | BD5: Density [lb/ftÂ³] | BE5: . | BG5: TIME | BH5: 120.000055555556 h | BJ5: TIME | BK5: 120 h | BM5: TIME | BN5: 120.000055555556 h | BQ5: TIME | BR5: 120 h
C6: 48.543058 | D6: 189.9156 | E6: 2326.2775 | F6: 48.110557 | H6: 0.009193761 | I6: =H6*5280 -> 48.543058 | J6: 129.81988 | K6: 2157.7074 | L6: 51.133394 | N6: 0.009193761 | O6: =N6*5280 -> 48.543058 | P6: 102.58734 | Q6: 2285.3 | R6: 51.267077 | U6: 48.543058 | V6: 160.35645 | W6: 2146.0188 | X6: 48.607428 | Z6: 48.543058 | AA6: 112.47148 | AB6: 2071.7 | AC6: 49.964886 | AE6: 48.543058 | AF6: 87.482857 | AG6: 2197.8031 | AH6: 50.533898 | AK6: 48.543058 | AL6: 135.9993 | AM6: 48.543058 | AN6: 1881.6107 | AO6: 48.543058 | AP6: 49.039273 | AR6: 48.543058 | AS6: 97.773421 | AT6: 48.543058 | AU6: 2072.753 | AV6: 48.543058 | AW6: 50.269422 | AY6: 48.543058 | AZ6: 77.776069 | BA6: 48.543058 | BB6: 2140.5248 | BC6: 48.543058 | BD6: 50.703278
C7: 145.62917 | D7: 189.7842 | E7: 2327.4044 | F7: 48.114596 | H7: 0.027581283 | I7: =H7*5280 -> 145.62917 | J7: 129.62971 | K7: 2159.442 | L7: 51.130728 | N7: 0.027581283 | O7: =N7*5280 -> 145.62917 | P7: 102.00601 | Q7: 2287.1231 | R7: 51.27563 | U7: 145.62917 | V7: 160.25954 | W7: 2147.7854 | X7: 48.611024 | Z7: 145.62917 | AA7: 111.64753 | AB7: 2073.5043 | AC7: 49.983028 | AE7: 145.62917 | AF7: 87.115819 | AG7: 2199.6291 | AH7: 50.544299 | AK7: 145.62917 | AL7: 135.92978 | AM7: 145.62917 | AN7: 1883.3903 | AO7: 145.62917 | AP7: 49.041776 | AR7: 145.62917 | AS7: 97.128823 | AT7: 145.62917 | AU7: 2074.5689 | AV7: 145.62917 | AW7: 50.283575 | AY7: 145.62917 | AZ7: 77.486287 | BA7: 145.62917 | BB7: 2142.3566 | BC7: 145.62917 | BD7: 50.709745 | BG7: Distance [ft] | BH7: Pressure [psia] | BJ7: Distance [ft] | BK7: Pressure [psia] | BM7: Distance [ft] | BN7: Temperature [°F] | BQ7: Distance [ft] | BR7: Temperature [°F]
C8: 222.08612 | D8: 189.71013 | E8: 2328.2906 | F8: 48.117075 | H8: 0.042061764 | I8: =H8*5280 -> 222.08612 | J8: 129.52124 | K8: 2160.8083 | L8: 51.136515 | N8: 0.042061764 | O8: =N8*5280 -> 222.08612 | P8: 101.67982 | Q8: 2288.559 | R8: 51.287497 | U8: 222.08612 | V8: 160.20176 | W8: 2149.1777 | X8: 48.61344 | Z8: 222.08612 | AA8: 111.27623 | AB8: 2074.9271 | AC8: 49.98937 | AE8: 222.08612 | AF8: 86.902825 | AG8: 2201.0664 | AH8: 50.545229 | AK8: 222.08612 | AL8: 135.88181 | AM8: 222.08612 | AN8: 1884.7928 | AO8: 222.08612 | AP8: 49.043762 | AR8: 222.08612 | AS8: 96.836071 | AT8: 222.08612 | AU8: 2075.9989 | AV8: 222.08612 | AW8: 50.28551 | AY8: 222.08612 | AZ8: 77.314513 | BA8: 222.08612 | BB8: 2143.7983 | BC8: 222.08612 | BD8: 50.71042 | BG8: 48.543058 | BH8: 1215.1683 | BJ8: 48.543058 | BK8: 1191.2192 | BM8: 48.543058 | BN8: 40.54643 | BQ8: 48.543058 | BR8: 40.687809
C9: 270.935 | D9: 189.65318 | E9: 2328.5256 | F9: 48.119179 | H9: 0.051313447 | I9: =H9*5280 -> 270.935 | J9: 129.43911 | K9: 2161.3304 | L9: 51.821063 | N9: 0.051313447 | O9: =N9*5280 -> 270.935 | P9: 101.43414 | Q9: 2289.1246 | R9: 52.25332 | U9: 270.935 | V9: 160.15714 | W9: 2149.7318 | X9: 48.614083 | Z9: 270.935 | AA9: 111.0657 | AB9: 2075.4927 | AC9: 49.979881 | AE9: 270.935 | AF9: 86.795149 | AG9: 2201.6393 | AH9: 50.531938 | AK9: 270.935 | AL9: 135.84603 | AM9: 270.935 | AN9: 1885.3512 | AO9: 270.935 | AP9: 49.044324 | AR9: 270.935 | AS9: 96.673855 | AT9: 270.935 | AU9: 2076.5689 | AV9: 270.935 | AW9: 50.281914 | AY9: 270.935 | AZ9: 77.229859 | BA9: 270.935 | BB9: 2144.3726 | BC9: 270.935 | BD9: 50.705862 | BG9: 145.62917 | BH9: 1216.4498 | BJ9: 145.62917 | BK9: 1192.2799 | BM9: 145.62917 | BN9: 40.832216 | BQ9: 145.62917 | BR9: 40.911197
C10: 312.805 | D10: 189.59495 | E10: 2328.3472 | F10: 48.120334 | H10: 0.059243371 | I10: =H10*5280 -> 312.805 | J10: 129.35615 | K10: 2161.3913 | L10: 51.979973 | N10: 0.059243371 | O10: =N10*5280 -> 312.805 | P10: 101.18847 | Q10: 2289.2203 | R10: 52.395731 | U10: 312.805 | V10: 160.13347 | W10: 2149.8231 | X10: 48.677091 | Z10: 312.805 | AA10: 111.14595 | AB10: 2075.587 | AC10: 50.998125 | AE10: 312.805 | AF10: 86.870515 | AG10: 2201.7336 | AH10: 51.706133 | AK10: 312.805 | AL10: 135.85075 | AM10: 312.805 | AN10: 1885.444 | AO10: 312.805 | AP10: 49.108062 | AR10: 312.805 | AS10: 96.999259 | AT10: 312.805 | AU10: 2076.6632 | AV10: 312.805 | AW10: 51.294439 | AY10: 312.805 | AZ10: 77.494225 | BA10: 312.805 | BB10: 2144.4683 | BC10: 312.805 | BD10: 51.873571 | BG10: 222.08612 | BH10: 1217.898 | BJ10: 222.08612 | BK10: 1193.7166 | BM10: 222.08612 | BN10: 40.902546 | BQ10: 222.08612 | BR10: 41.010324
C11: 375.49 | D11: 189.4791 | E11: 2328.4371 | F11: 48.12318 | H11: 0.07111553 | I11: =H11*5280 -> 375.49 | J11: 129.19143 | K11: 2161.8584 | L11: 51.398881 | N11: 0.07111553 | O11: =N11*5280 -> 375.49 | P11: 100.71165 | Q11: 2289.7381 | R11: 51.528763 | U11: 375.49 | V11: 160.01269 | W11: 2150.3221 | X11: 48.617834 | Z11: 375.49 | AA11: 110.51604 | AB11: 2076.1019 | AC11: 49.991655 | AE11: 375.49 | AF11: 86.208835 | AG11: 2202.2557 | AH11: 50.54634 | AK11: 375.49 | AL11: 135.72739 | AM11: 375.49 | AN11: 1885.9458 | AO11: 375.49 | AP11: 49.047507 | AR11: 375.49 | AS11: 96.235699 | AT11: 375.49 | AU11: 2077.1824 | AV11: 375.49 | AW11: 50.291241 | AY11: 375.49 | AZ11: 76.756801 | BA11: 375.49 | BB11: 2144.9919 | BC11: 375.49 | BD11: 50.716519 | BG11: 270.935 | BH11: 1218.4745 | BJ11: 270.935 | BK11: 1194.2911 | BM11: 270.935 | BN11: 40.926095 | BQ11: 270.935 | BR11: 41.051089
C12: 500.49 | D12: 189.24933 | E12: 2328.9752 | F12: 48.129254 | H12: 0.094789773 | I12: =H12*5280 -> 500.49 | J12: 128.86473 | K12: 2163.1477 | L12: 51.382725 | N12: 0.094789773 | O12: =N12*5280 -> 500.49 | P12: 99.778549 | Q12: 2291.1348 | R12: 51.53357 | U12: 500.49 | V12: 159.83258 | W12: 2151.6767 | X12: 48.62379 | Z12: 500.49 | AA12: 110.13669 | AB12: 2077.4856 | AC12: 50.00298 | AE12: 500.49 | AF12: 85.533637 | AG12: 2203.6553 | AH12: 50.568346 | AK12: 500.49 | AL12: 135.58346 | AM12: 500.49 | AN12: 1887.3107 | AO12: 500.49 | AP12: 49.052283 | AR12: 500.49 | AS12: 95.935477 | AT12: 500.49 | AU12: 2078.5748 | AV12: 500.49 | AW12: 50.299094 | AY12: 500.49 | AZ12: 76.216855 | BA12: 500.49 | BB12: 2146.3959 | BC12: 500.49 | BD12: 50.731158 | BG12: 312.805 | BH12: 1218.57 | BJ12: 312.805 | BK12: 1194.3847 | BM12: 312.805 | BN12: 40.934651 | BQ12: 312.805 | BR12: 41.067321
C13: 646.24 | D13: 189.07889 | E13: 2329.2319 | F13: 48.133912 | H13: 0.12239394 | I13: =H13*5280 -> 646.24 | J13: 128.62051 | K13: 2164.2587 | L13: 51.738371 | N13: 0.12239394 | O13: =N13*5280 -> 646.24 | P13: 99.073903 | Q13: 2292.3735 | R13: 51.955882 | U13: 646.24 | V13: 159.69644 | W13: 2152.882 | X13: 48.627055 | Z13: 646.24 | AA13: 109.91597 | AB13: 2078.7169 | AC13: 50.021128 | AE13: 646.24 | AF13: 85.047313 | AG13: 2204.9012 | AH13: 50.585202 | AK13: 646.24 | AL13: 135.47264 | AM13: 646.24 | AN13: 1888.5246 | AO13: 646.24 | AP13: 49.05498 | AR13: 646.24 | AS13: 95.759023 | AT13: 646.24 | AU13: 2079.812 | AV13: 646.24 | AW13: 50.313191 | AY13: 646.24 | AZ13: 75.826309 | BA13: 646.24 | BB13: 2147.6461 | BC13: 646.24 | BD13: 50.74292 | BG13: 375.49 | BH13: 1219.0889 | BJ13: 375.49 | BK13: 1194.9008 | BM13: 375.49 | BN13: 40.93167 | BQ13: 375.49 | BR13: 41.070299
C14: 771.24 | D14: 188.90663 | E14: 2329.0288 | F14: 48.137932 | H14: 0.14606818 | I14: =H14*5280 -> 771.24 | J14: 128.37526 | K14: 2164.7765 | L14: 51.76808 | N14: 0.14606818 | O14: =N14*5280 -> 771.24 | P14: 98.361949 | Q14: 2292.9971 | R14: 51.983975 | U14: 771.24 | V14: 159.56182 | W14: 2153.4868 | X14: 48.651015 | Z14: 771.24 | AA14: 109.70589 | AB14: 2079.3362 | AC14: 50.055076 | AE14: 771.24 | AF14: 84.541639 | AG14: 2205.5263 | AH14: 50.637941 | AK14: 771.24 | AL14: 135.3727 | AM14: 771.24 | AN14: 1889.1338 | AO14: 771.24 | AP14: 49.078328 | AR14: 771.24 | AS14: 95.598661 | AT14: 771.24 | AU14: 2080.4342 | AV14: 771.24 | AW14: 50.34654 | AY14: 771.24 | AZ14: 75.428527 | BA14: 771.24 | BB14: 2148.2727 | BC14: 771.24 | BD14: 50.794354 | BG14: 500.49 | BH14: 1220.4984 | BJ14: 500.49 | BK14: 1196.3048 | BM14: 500.49 | BN14: 40.925845 | BQ14: 500.49 | BR14: 41.067222
C15: 896.24 | D15: 188.73601 | E15: 2329.4103 | F15: 48.142314 | H15: 0.16974242 | I15: =H15*5280 -> 896.24 | J15: 128.13127 | K15: 2165.9122 | L15: 51.289757 | N15: 0.16974242 | O15: =N15*5280 -> 896.24 | P15: 97.650697 | Q15: 2294.2401 | R15: 51.466859 | U15: 896.24 | V15: 159.41771 | W15: 2154.6848 | X15: 48.63474 | Z15: 896.24 | AA15: 109.48467 | AB15: 2080.5604 | AC15: 50.016115 | AE15: 896.24 | AF15: 83.997499 | AG15: 2206.7649 | AH15: 50.597631 | AK15: 896.24 | AL15: 135.2476 | AM15: 896.24 | AN15: 1890.3405 | AO15: 896.24 | AP15: 49.060979 | AR15: 896.24 | AS15: 95.412757 | AT15: 896.24 | AU15: 2081.667 | AV15: 896.24 | AW15: 50.31035 | AY15: 896.24 | AZ15: 74.984503 | BA15: 896.24 | BB15: 2149.5157 | BC15: 896.24 | BD15: 50.754943 | BG15: 646.24 | BH15: 1221.7518 | BJ15: 646.24 | BK15: 1197.5517 | BM15: 646.24 | BN15: 40.920177 | BQ15: 646.24 | BR15: 41.062629
C16: 1021.24 | D16: 188.56702 | E16: 2330.3806 | F16: 48.147009 | H16: 0.19341667 | I16: =H16*5280 -> 1021.24 | J16: 127.8887 | K16: 2167.6439 | L16: 51.27754 | N16: 0.19341667 | O16: =N16*5280 -> 1021.24 | P16: 96.946411 | Q16: 2296.0879 | R16: 51.471504 | U16: 1021.24 | V16: 159.28662 | W16: 2156.476 | X16: 48.654124 | Z16: 1021.24 | AA16: 109.29601 | AB16: 2082.3907 | AC16: 50.067574 | AE16: 1021.24 | AF16: 83.496613 | AG16: 2208.6171 | AH16: 50.665353 | AK16: 1021.24 | AL16: 135.14718 | AM16: 1021.24 | AN16: 1892.1433 | AO16: 1021.24 | AP16: 49.079152 | AR16: 1021.24 | AS16: 95.269747 | AT16: 1021.24 | AU16: 2083.5075 | AV16: 1021.24 | AW16: 50.356378 | AY16: 1021.24 | AZ16: 74.591113 | BA16: 1021.24 | BB16: 2151.3721 | BC16: 1021.24 | BD16: 50.816385 | BG16: 771.24 | BH16: 1222.3813 | BJ16: 771.24 | BK16: 1198.1755 | BM16: 771.24 | BN16: 40.916375 | BQ16: 771.24 | BR16: 41.058291
C17: 1146.24 | D17: 188.40014 | E17: 2332.1356 | F17: 48.152172 | H17: 0.21709091 | I17: =H17*5280 -> 1146.24 | J17: 127.64793 | K17: 2170.1966 | L17: 51.033759 | N17: 0.21709091 | O17: =N17*5280 -> 1146.24 | P17: 96.254005 | Q17: 2298.7653 | R17: 51.270542 | U17: 1146.24 | V17: 159.1455 | W17: 2159.0606 | X17: 48.643967 | Z17: 1146.24 | AA17: 109.0884 | AB17: 2085.0319 | AC17: 50.02777 | AE17: 1146.24 | AF17: 82.974973 | AG17: 2211.2901 | AH17: 50.620736 | AK17: 1146.24 | AL17: 135.02593 | AM17: 1146.24 | AN17: 1894.7467 | AO17: 1146.24 | AP17: 49.068102 | AR17: 1146.24 | AS17: 95.093563 | AT17: 1146.24 | AU17: 2086.1646 | AV17: 1146.24 | AW17: 50.319059 | AY17: 1146.24 | AZ17: 74.164279 | BA17: 1146.24 | BB17: 2154.0539 | BC17: 1146.24 | BD17: 50.773316 | BG17: 896.24 | BH17: 1223.6276 | BJ17: 896.24 | BK17: 1199.416 | BM17: 896.24 | BN17: 40.910441 | BQ17: 896.24 | BR17: 41.053181
C18: 1271.24 | D18: 188.23539 | E18: 2334.6752 | F18: 48.158021 | H18: 0.24076515 | I18: =H18*5280 -> 1271.24 | J18: 127.40916 | K18: 2173.5499 | L18: 51.032523 | N18: 0.24076515 | O18: =N18*5280 -> 1271.24 | P18: 95.574757 | Q18: 2302.2534 | R18: 51.281454 | U18: 1271.24 | V18: 159.01437 | W18: 2162.4371 | X18: 48.650247 | Z18: 1271.24 | AA18: 108.905 | AB18: 2088.4838 | AC18: 50.034937 | AE18: 1271.24 | AF18: 82.484725 | AG18: 2214.7812 | AH18: 50.632903 | AK18: 1271.24 | AL18: 134.9188 | AM18: 1271.24 | AN18: 1898.1479 | AO18: 1271.24 | AP18: 49.072784 | AR18: 1271.24 | AS18: 94.950589 | AT18: 1271.24 | AU18: 2089.6354 | AV18: 1271.24 | AW18: 50.32371 | AY18: 1271.24 | AZ18: 73.771213 | BA18: 1271.24 | BB18: 2157.5565 | BC18: 1271.24 | BD18: 50.782886 | BG18: 1021.24 | BH18: 1225.49 | BJ18: 1021.24 | BK18: 1201.2726 | BM18: 1021.24 | BN18: 40.905575 | BQ18: 1021.24 | BR18: 41.04782
C19: 1396.24 | D19: 188.07011 | E19: 2336.9305 | F19: 48.163827 | H19: 0.26443939 | I19: =H19*5280 -> 1396.24 | J19: 127.17052 | K19: 2176.6043 | L19: 51.105938 | N19: 0.26443939 | O19: =N19*5280 -> 1396.24 | P19: 94.906669 | Q19: 2305.4443 | R19: 51.35359 | U19: 1396.24 | V19: 158.88173 | W19: 2165.5264 | X19: 48.654448 | Z19: 1396.24 | AA19: 108.89004 | AB19: 2091.6369 | AC19: 50.928718 | AE19: 1396.24 | AF19: 82.023475 | AG19: 2217.9706 | AH19: 50.423176 | AK19: 1396.24 | AL19: 134.81494 | AM19: 1396.24 | AN19: 1901.2589 | AO19: 1396.24 | AP19: 49.076268 | AR19: 1396.24 | AS19: 95.445679 | AT19: 1396.24 | AU19: 2092.7943 | AV19: 1396.24 | AW19: 52.154197 | AY19: 1396.24 | AZ19: 73.448581 | BA19: 1396.24 | BB19: 2160.7546 | BC19: 1396.24 | BD19: 50.567304 | BG19: 1146.24 | BH19: 1228.1777 | BJ19: 1146.24 | BK19: 1203.9547 | BM19: 1146.24 | BN19: 40.900321 | BQ19: 1146.24 | BR19: 41.042093
... C92: 7838.61 | D92: 179.35923 | E92: 2279.4927 | F92: 48.34249 | H92: 1.4845852 | I92: =H92*5280 -> 7838.61 | J92: 115.41673 | K92: 2151.4055 | L92: 51.909498 | N92: 1.4845852 | O92: =N92*5280 -> 7838.61 | P92: 69.261097 | Q92: 2280.2918 | R92: 52.432389 | U92: 7838.61 | V92: 151.86972 | W92: 2149.3111 | X92: 48.812341 | Z92: 7838.61 | AA92: 99.351121 | AB92: 2074.5094 | AC92: 50.233657 | AE92: 7838.61 | AF92: 63.130351 | AG92: 2195.6913 | AH92: 51.001771 | AK92: 7838.61 | AL92: 129.1874 | AM92: 7838.61 | AN92: 1884.9465 | AO92: 7838.61 | AP92: 49.196098 | AR92: 7838.61 | AS92: 87.299995 | AT92: 7838.61 | AU92: 2075.7031 | AV92: 7838.61 | AW92: 50.4783 | AY92: 7838.61 | AZ92: 58.301744 | BA92: 7838.61 | BB92: 2138.677 | BC92: 7838.61 | BD92: 51.075136 | BG92: 7601.86 | BH92: 1217.8306 | BJ92: 7601.86 | BK92: 1193.115 | BM92: 7601.86 | BN92: 40.682588 | BQ92: 7601.86 | BR92: 40.788057

Sheet Density
A1: Profile Name | B1: Content_Install | C1: Content_flooded | D1: Content_design | E1: Content_early | F1: Content_mid | G1: Content_lat | H1: Content_earlyPCD | I1: Content_midPCD | J1: Content_latPCD | K1: Content_earlyFCD | L1: Content_midFCD | M1: Content_latFCD
A2: KP | B2: Content density | C2: Content density | D2: Content density | E2: Content density | F2: Content density | G2: Content density | H2: Content density | I2: Content density | J2: Content density | K2: Content density | L2: Content density | M2: Content density
A3: [m] | B3: [kg/m3] | C3: [kg/m3] | D3: [kg/m3] | E3: [kg/m3] | F3: [kg/m3] | G3: [kg/m3] | H3: [kg/m3] | I3: [kg/m3] | J3: [kg/m3] | K3: [kg/m3] | L3: [kg/m3] | M3: [kg/m3]
A4: Min | B4: 0 | C4: 1020 | D4: 368.4 | E4: =MIN('FL6 data'!F$6:F$568)*16.018 -> 770.63491 | F4: =MIN('FL6 data'!L$6:L$568)*16.018 -> 817.43895 | G4: =MIN('FL6 data'!R$6:R$568)*16.018 -> 821.19604 | H4: =MIN('FL6 data'!X$6:X$568)*16.018 -> 777.725 | I4: =MIN('FL6 data'!AC$6:AC$568)*16.018 -> 800.33755 | J4: =MIN('FL6 data'!AH$6:AH$568)*16.018 -> 792.22398 | K4: =MIN('FL6 data'!AP$6:AP$568)*16.018 -> 784.94479 | L4: =MIN('FL6 data'!AW$6:AW$568)*16.018 -> 802.0894 | M4: =MIN('FL6 data'!BD$6:BD$568)*16.018 -> 791.08782
A5: Max | B5: 0 | C5: 1020 | D5: 921.1 | E5: =MAX('FL6 data'!F$6:F$568)*16.018 -> 774.35 | F5: =MAX('FL6 data'!L$6:L$568)*16.018 -> 871.90438 | G5: =MAX('FL6 data'!R$6:R$568)*16.018 -> 1005.3009 | H5: =MAX('FL6 data'!X$6:X$568)*16.018 -> 797.18354 | I5: =MAX('FL6 data'!AC$6:AC$568)*16.018 -> 1155.4176 | J5: =MAX('FL6 data'!AH$6:AH$568)*16.018 -> 1147.2898 | K5: =MAX('FL6 data'!AP$6:AP$568)*16.018 -> 803.67515 | L5: =MAX('FL6 data'!AW$6:AW$568)*16.018 -> 1192.1245 | M5: =MAX('FL6 data'!BD$6:BD$568)*16.018 -> 1178.6859
A6: Avg | B6: 0 | C6: 1020 | D6: 921.1 | E6: =AVERAGE('FL6 data'!F$6:F$568)*16.018 -> 772.66029 | F6: =AVERAGE('FL6 data'!L$6:L$568)*16.018 -> 848.14085 | G6: =AVERAGE('FL6 data'!R$6:R$568)*16.018 -> 941.4282 | H6: =AVERAGE('FL6 data'!X$6:X$568)*16.018 -> 780.89624 | I6: =AVERAGE('FL6 data'!AC$6:AC$568)*16.018 -> 850.68294 | J6: =AVERAGE('FL6 data'!AH$6:AH$568)*16.018 -> 935.23788 | K6: =AVERAGE('FL6 data'!AP$6:AP$568)*16.018 -> 787.39712 | L6: =AVERAGE('FL6 data'!AW$6:AW$568)*16.018 -> 854.12122 | M6: =AVERAGE('FL6 data'!BD$6:BD$568)*16.018 -> 936.17752

Sheet Temperature
A1: Profile Name | B1: Landing_Temp | C1: Flooded_Temp | D1: Hydrotest_Temp | E1: FillContent_Temp | F1: Design_Temp | G1: OPSS_Early_Temp | H1: OPSS_Mid_Temp | I1: OPSS_Lat_Temp | J1: PCD_Early_Temp | K1: PCD_Mid_Temp | L1: PCD_Lat_Temp | M1: HCD_Early_Temp | N1: HCD_Mid_Temp | O1: HCD_Lat_Temp | P1: FCD_Early_Temp | Q1: FCD_Mid_Temp | S1: Profile Name | U1: =G1 -> OPSS_Early_Temp | AC1: Profile Name
A2: KP | B2: Temperature | C2: Temperature | D2: Temperature | E2: Temperature | F2: Temperature | G2: Temperature | H2: Temperature | I2: Temperature | J2: Temperature | K2: Temperature | L2: Temperature | M2: Temperature | N2: Temperature | O2: Temperature | P2: Temperature | Q2: Temperature | S2: KP | T2: KP_reverse | U2: =G2 -> Temperature | V2: Pressure | Y2: KP | Z2: Temp | AC2: KP | AD2: Row1 | AE2: Row2 | AF2: KP1 | AG2: KP2 | AH2: Temp1 | AI2: Temp2 | AJ2: Temp
A3: [m] | B3: [C] | C3: [C] | D3: [C] | E3: [C] | F3: [C] | G3: [C] | H3: [C] | I3: [C] | J3: [C] | K3: [C] | L3: [C] | M3: [C] | N3: [C] | O3: [C] | P3: [C] | Q3: [C] | S3: [ft] | T3: [ft] | U3: =G3 -> [C] | V3: [bar] | Y3: [m] | Z3: [°C] | AC3: [m]
A4: 0 | B4: =AJ4 -> 4.33 | C4: 4.2 | D4: 4.2 | E4: 4.2 | F4: 148.9 | G4: =G5 -> 87.730889 | H4: =H5 -> 54.344379 | I4: =I5 -> 39.21519 | J4: =J5 -> 71.309139 | K4: =K5 -> 44.70638 | L4: =L5 -> 30.82381 | M4: =M5 -> 57.777389 | N4: =N5 -> 36.54079 | ... P4: =P5 -> 4.7480168 | Q4: =P4 -> 4.7480168 | S4: =A4*3.281 -> 0 | T4: =$S$440-S4 -> 0 | U4: =G4 -> 87.730889 | V4: =Pressure!K4 -> 160.39218 | X4: 2nd End | Y4: 13575.893 | Z4: =22.6 -> 22.6 | AC4: 0 | AD4: =MATCH(AC4,$Y$11:$Y$15,1) -> 1 | AE4: =AD4+1 -> 2 | AF4: {=INDEX($Y$11:$Y$15,$AD4,0)} -> 0 | AG4: {=INDEX($Y$11:$Y$15,$AE4,0)} -> 12311.893 | AH4: {=INDEX($Z$11:$Z$15,$AD4,0)} -> 4.33 | AI4: {=INDEX($Z$11:$Z$15,$AE4,0)} -> 6.2 | AJ4: =IF(AC4<>$Y$15, FORECAST(AC4,AH4:AI4,AF4:AG4),AH4) -> 4.33
A5: ='FL6 data'!C6*0.3048 -> 14.795924 | B5: =AJ5 -> 4.3322473 | C5: 4.2 | D5: 4.2 | E5: 4.2 | F5: 148.9 | G5: =('FL6 data'!D6-32)*5/9 -> 87.730889 | H5: =('FL6 data'!J6-32)*5/9 -> 54.344379 | I5: =('FL6 data'!P6-32)*5/9 -> 39.21519 | J5: =('FL6 data'!V6-32)*5/9 -> 71.309139 | K5: =('FL6 data'!AA6-32)*5/9 -> 44.70638 | L5: =('FL6 data'!AF6-32)*5/9 -> 30.82381 | M5: =('FL6 data'!AL6-32)*5/9 -> 57.777389 | N5: =('FL6 data'!AS6-32)*5/9 -> 36.54079 | O5: =('FL6 data'!AZ6-32)*5/9 -> 25.43115 | P5: =('FL6 data'!BN8-32)*5/9 -> 4.7480168 | Q5: =P5 -> 4.7480168 | S5: =A5*3.281 -> 48.545427 | T5: =$S$440-S5 -> -48.545427 | U5: =G5 -> 87.730889 | V5: =Pressure!K5 -> 160.39218 | X5: -200 | Y5: =Y4-200 -> 13375.893 | Z5: 13.5 | AC5: 14.795924 | AD5: =MATCH(AC5,$Y$11:$Y$15,1) -> 1 | AE5: =AD5+1 -> 2 | AF5: {=INDEX($Y$11:$Y$15,$AD5,0)} -> 0 | AG5: {=INDEX($Y$11:$Y$15,$AE5,0)} -> 12311.893 | AH5: {=INDEX($Z$11:$Z$15,$AD5,0)} -> 4.33 | AI5: {=INDEX($Z$11:$Z$15,$AE5,0)} -> 6.2 | AJ5: =IF(AC5<>$Y$15, FORECAST(AC5,AH5:AI5,AF5:AG5),AH5) -> 4.3322473
A6: ='FL6 data'!C7*0.3048 -> 44.387772 | B6: =AJ6 -> 4.3367419 | C6: 4.2 | D6: 4.2 | E6: 4.2 | F6: 148.9 | G6: =('FL6 data'!D7-32)*5/9 -> 87.657889 | H6: =('FL6 data'!J7-32)*5/9 -> 54.238729 | I6: =('FL6 data'!P7-32)*5/9 -> 38.89223 | J6: =('FL6 data'!V7-32)*5/9 -> 71.255299 | K6: =('FL6 data'!AA7-32)*5/9 -> 44.24863 | L6: =('FL6 data'!AF7-32)*5/9 -> 30.6199 | M6: =('FL6 data'!AL7-32)*5/9 -> 57.738769 | N6: =('FL6 data'!AS7-32)*5/9 -> 36.18268 | O6: =('FL6 data'!AZ7-32)*5/9 -> 25.27016 | P6: =('FL6 data'!BN9-32)*5/9 -> 4.9067868 | Q6: =P6 -> 4.9067868 | S6: =A6*3.281 -> 145.63628 | T6: =$S$440-S6 -> -145.63628 | U6: =G6 -> 87.657889 | V6: =Pressure!K6 -> 160.46988 | X6: -400 | Y6: =Y5-400 -> 12975.893 | Z6: 8.2 | AC6: 44.387772 | AD6: =MATCH(AC6,$Y$11:$Y$15,1) -> 1 | AE6: =AD6+1 -> 2 | AF6: {=INDEX($Y$11:$Y$15,$AD6,0)} -> 0 | AG6: {=INDEX($Y$11:$Y$15,$AE6,0)} -> 12311.893 | AH6: {=INDEX($Z$11:$Z$15,$AD6,0)} -> 4.33 | AI6: {=INDEX($Z$11:$Z$15,$AE6,0)} -> 6.2 | AJ6: =IF(AC6<>$Y$15, FORECAST(AC6,AH6:AI6,AF6:AG6),AH6) -> 4.3367419
A7: ='FL6 data'!C8*0.3048 -> 67.691848 | B7: =AJ7 -> 4.3402814 | C7: 4.2 | D7: 4.2 | E7: 4.2 | F7: 148.9 | G7: =('FL6 data'!D8-32)*5/9 -> 87.616739 | H7: =('FL6 data'!J8-32)*5/9 -> 54.178469 | I7: =('FL6 data'!P8-32)*5/9 -> 38.71101 | J7: =('FL6 data'!V8-32)*5/9 -> 71.223199 | K7: =('FL6 data'!AA8-32)*5/9 -> 44.04235 | L7: =('FL6 data'!AF8-32)*5/9 -> 30.50157 | M7: =('FL6 data'!AL8-32)*5/9 -> 57.712119 | N7: =('FL6 data'!AS8-32)*5/9 -> 36.02004 | O7: =('FL6 data'!AZ8-32)*5/9 -> 25.17473 | P7: =('FL6 data'!BN10-32)*5/9 -> 4.9458588 | Q7: =P7 -> 4.9458588 | S7: =A7*3.281 -> 222.09695 | T7: =$S$440-S7 -> -222.09695 | U7: =G7 -> 87.616739 | V7: =Pressure!K7 -> 160.53098 | X7: -664 | Y7: =Y6-664 -> 12311.893 | Z7: 6.2 | AC7: 67.691848 | AD7: =MATCH(AC7,$Y$11:$Y$15,1) -> 1 | AE7: =AD7+1 -> 2 | AF7: {=INDEX($Y$11:$Y$15,$AD7,0)} -> 0 | AG7: {=INDEX($Y$11:$Y$15,$AE7,0)} -> 12311.893 | AH7: {=INDEX($Z$11:$Z$15,$AD7,0)} -> 4.33 | AI7: {=INDEX($Z$11:$Z$15,$AE7,0)} -> 6.2 | AJ7: =IF(AC7<>$Y$15, FORECAST(AC7,AH7:AI7,AF7:AG7),AH7) -> 4.3402814
A8: ='FL6 data'!C9*0.3048 -> 82.580988 | B8: =AJ8 -> 4.3425429 | C8: 4.2 | D8: 4.2 | E8: 4.2 | F8: 148.9 | G8: =('FL6 data'!D9-32)*5/9 -> 87.585099 | H8: =('FL6 data'!J9-32)*5/9 -> 54.132839 | I8: =('FL6 data'!P9-32)*5/9 -> 38.57452 | J8: =('FL6 data'!V9-32)*5/9 -> 71.198409 | K8: =('FL6 data'!AA9-32)*5/9 -> 43.92539 | L8: =('FL6 data'!AF9-32)*5/9 -> 30.44175 | M8: =('FL6 data'!AL9-32)*5/9 -> 57.692239 | N8: =('FL6 data'!AS9-32)*5/9 -> 35.92992 | O8: =('FL6 data'!AZ9-32)*5/9 -> 25.1277 | P8: =('FL6 data'!BN11-32)*5/9 -> 4.9589418 | Q8: =P8 -> 4.9589418 | S8: =A8*3.281 -> 270.94822 | T8: =$S$440-S8 -> -270.94822 | U8: =G8 -> 87.585099 | V8: =Pressure!K8 -> 160.54718 | Y8: 0 | Z8: 4.2 | AC8: 82.580988 | AD8: =MATCH(AC8,$Y$11:$Y$15,1) -> 1 | AE8: =AD8+1 -> 2 | AF8: {=INDEX($Y$11:$Y$15,$AD8,0)} -> 0 | AG8: {=INDEX($Y$11:$Y$15,$AE8,0)} -> 12311.893 | AH8: {=INDEX($Z$11:$Z$15,$AD8,0)} -> 4.33 | AI8: {=INDEX($Z$11:$Z$15,$AE8,0)} -> 6.2 | AJ8: =IF(AC8<>$Y$15, FORECAST(AC8,AH8:AI8,AF8:AG8),AH8) -> 4.3425429
A9: ='FL6 data'!C10*0.3048 -> 95.342964 | B9: =AJ9 -> 4.3444812 | C9: 4.2 | D9: 4.2 | E9: 4.2 | F9: 148.9 | G9: =('FL6 data'!D10-32)*5/9 -> 87.552749 | H9: =('FL6 data'!J10-32)*5/9 -> 54.086749 | I9: =('FL6 data'!P10-32)*5/9 -> 38.43804 | J9: =('FL6 data'!V10-32)*5/9 -> 71.185259 | K9: =('FL6 data'!AA10-32)*5/9 -> 43.96997 | L9: =('FL6 data'!AF10-32)*5/9 -> 30.48362 | M9: =('FL6 data'!AL10-32)*5/9 -> 57.694859 | N9: =('FL6 data'!AS10-32)*5/9 -> 36.1107 | O9: =('FL6 data'!AZ10-32)*5/9 -> 25.27457 | P9: =('FL6 data'!BN12-32)*5/9 -> 4.9636948 | Q9: =P9 -> 4.9636948 | S9: =A9*3.281 -> 312.82026 | T9: =$S$440-S9 -> -312.82026 | U9: =G9 -> 87.552749 | V9: =Pressure!K9 -> 160.53488 | AC9: 95.342964 | AD9: =MATCH(AC9,$Y$11:$Y$15,1) -> 1 | AE9: =AD9+1 -> 2 | AF9: {=INDEX($Y$11:$Y$15,$AD9,0)} -> 0 | AG9: {=INDEX($Y$11:$Y$15,$AE9,0)} -> 12311.893 | AH9: {=INDEX($Z$11:$Z$15,$AD9,0)} -> 4.33 | AI9: {=INDEX($Z$11:$Z$15,$AE9,0)} -> 6.2 | AJ9: =IF(AC9<>$Y$15, FORECAST(AC9,AH9:AI9,AF9:AG9),AH9) -> 4.3444812
A10: ='FL6 data'!C11*0.3048 -> 114.44935 | B10: =AJ10 -> 4.3473832 | C10: 4.2 | D10: 4.2 | E10: 4.2 | F10: 148.9 | G10: =('FL6 data'!D11-32)*5/9 -> 87.488389 | H10: =('FL6 data'!J11-32)*5/9 -> 53.995239 | I10: =('FL6 data'!P11-32)*5/9 -> 38.17314 | J10: =('FL6 data'!V11-32)*5/9 -> 71.118159 | K10: =('FL6 data'!AA11-32)*5/9 -> 43.62002 | L10: =('FL6 data'!AF11-32)*5/9 -> 30.11602 | M10: =('FL6 data'!AL11-32)*5/9 -> 57.626329 | N10: =('FL6 data'!AS11-32)*5/9 -> 35.6865 | O10: =('FL6 data'!AZ11-32)*5/9 -> 24.86489 | P10: =('FL6 data'!BN13-32)*5/9 -> 4.9620388 | Q10: =P10 -> 4.9620388 | S10: =A10*3.281 -> 375.50832 | T10: =$S$440-S10 -> -375.50832 | U10: =G10 -> 87.488389 | V10: =Pressure!K10 -> 160.54108 | AC10: 114.44935 | AD10: =MATCH(AC10,$Y$11:$Y$15,1) -> 1 | AE10: =AD10+1 -> 2 | AF10: {=INDEX($Y$11:$Y$15,$AD10,0)} -> 0 | AG10: {=INDEX($Y$11:$Y$15,$AE10,0)} -> 12311.893 | AH10: {=INDEX($Z$11:$Z$15,$AD10,0)} -> 4.33 | AI10: {=INDEX($Z$11:$Z$15,$AE10,0)} -> 6.2 | AJ10: =IF(AC10<>$Y$15, FORECAST(AC10,AH10:AI10,AF10:AG10),AH10) -> 4.3473832
A11: ='FL6 data'!C12*0.3048 -> 152.54935 | B11: =AJ11 -> 4.3531701 | C11: 4.2 | D11: 4.2 | E11: 4.2 | F11: 148.9 | G11: =('FL6 data'!D12-32)*5/9 -> 87.360739 | H11: =('FL6 data'!J12-32)*5/9 -> 53.813739 | I11: =('FL6 data'!P12-32)*5/9 -> 37.65475 | J11: =('FL6 data'!V12-32)*5/9 -> 71.018099 | K11: =('FL6 data'!AA12-32)*5/9 -> 43.40927 | L11: =('FL6 data'!AF12-32)*5/9 -> 29.74091 | M11: =('FL6 data'!AL12-32)*5/9 -> 57.546369 | N11: =('FL6 data'!AS12-32)*5/9 -> 35.51971 | O11: =('FL6 data'!AZ12-32)*5/9 -> 24.56492 | P11: =('FL6 data'!BN14-32)*5/9 -> 4.9588028 | Q11: =P11 -> 4.9588028 | S11: =A11*3.281 -> 500.51442 | T11: =$S$440-S11 -> -500.51442 | U11: =G11 -> 87.360739 | V11: =Pressure!K11 -> 160.57818 | Y11: =Y8 -> 0 | Z11: =AB15 -> 4.33 | AC11: 152.54935 | AD11: =MATCH(AC11,$Y$11:$Y$15,1) -> 1 | AE11: =AD11+1 -> 2 | AF11: {=INDEX($Y$11:$Y$15,$AD11,0)} -> 0 | AG11: {=INDEX($Y$11:$Y$15,$AE11,0)} -> 12311.893 | AH11: {=INDEX($Z$11:$Z$15,$AD11,0)} -> 4.33 | AI11: {=INDEX($Z$11:$Z$15,$AE11,0)} -> 6.2 | AJ11: =IF(AC11<>$Y$15, FORECAST(AC11,AH11:AI11,AF11:AG11),AH11) -> 4.3531701
A12: ='FL6 data'!C13*0.3048 -> 196.97395 | B12: =AJ12 -> 4.3599175 | C12: 4.2 | D12: 4.2 | E12: 4.2 | F12: 148.9 | G12: =('FL6 data'!D13-32)*5/9 -> 87.266049 | H12: =('FL6 data'!J13-32)*5/9 -> 53.678059 | I12: =('FL6 data'!P13-32)*5/9 -> 37.26328 | J12: =('FL6 data'!V13-32)*5/9 -> 70.942469 | K12: =('FL6 data'!AA13-32)*5/9 -> 43.28665 | L12: =('FL6 data'!AF13-32)*5/9 -> 29.47073 | M12: =('FL6 data'!AL13-32)*5/9 -> 57.484799 | N12: =('FL6 data'!AS13-32)*5/9 -> 35.42168 | O12: =('FL6 data'!AZ13-32)*5/9 -> 24.34795 | P12: =('FL6 data'!BN15-32)*5/9 -> 4.9556538 | Q12: =P12 -> 4.9556538 | S12: =A12*3.281 -> 646.27154 | T12: =$S$440-S12 -> -646.27154 | U12: =G12 -> 87.266049 | V12: =Pressure!K12 -> 160.59588 | Y12: =Y7 -> 12311.893 | Z12: =Z7 -> 6.2 | AC12: 196.97395 | AD12: =MATCH(AC12,$Y$11:$Y$15,1) -> 1 | AE12: =AD12+1 -> 2 | AF12: {=INDEX($Y$11:$Y$15,$AD12,0)} -> 0 | AG12: {=INDEX($Y$11:$Y$15,$AE12,0)} -> 12311.893 | AH12: {=INDEX($Z$11:$Z$15,$AD12,0)} -> 4.33 | AI12: {=INDEX($Z$11:$Z$15,$AE12,0)} -> 6.2 | AJ12: =IF(AC12<>$Y$15, FORECAST(AC12,AH12:AI12,AF12:AG12),AH12) -> 4.3599175
A13: ='FL6 data'!C14*0.3048 -> 235.07395 | B13: =AJ13 -> 4.3657044 | C13: 4.2 | D13: 4.2 | E13: 4.2 | F13: 148.9 | G13: =('FL6 data'!D14-32)*5/9 -> 87.170349 | H13: =('FL6 data'!J14-32)*5/9 -> 53.541809 | I13: =('FL6 data'!P14-32)*5/9 -> 36.86775 | J13: =('FL6 data'!V14-32)*5/9 -> 70.867679 | K13: =('FL6 data'!AA14-32)*5/9 -> 43.16994 | L13: =('FL6 data'!AF14-32)*5/9 -> 29.1898 | M13: =('FL6 data'!AL14-32)*5/9 -> 57.429279 | N13: =('FL6 data'!AS14-32)*5/9 -> 35.33259 | O13: =('FL6 data'!AZ14-32)*5/9 -> 24.12696 | P13: =('FL6 data'!BN16-32)*5/9 -> 4.9535418 | Q13: =P13 -> 4.9535418 | S13: =A13*3.281 -> 771.27764 | T13: =$S$440-S13 -> -771.27764 | U13: =G13 -> 87.170349 | V13: =Pressure!K13 -> 160.58188 | Y13: =Y6 -> 12975.893 | Z13: =Z6 -> 8.2 | AC13: 235.07395 | AD13: =MATCH(AC13,$Y$11:$Y$15,1) -> 1 | AE13: =AD13+1 -> 2 | AF13: {=INDEX($Y$11:$Y$15,$AD13,0)} -> 0 | AG13: {=INDEX($Y$11:$Y$15,$AE13,0)} -> 12311.893 | AH13: {=INDEX($Z$11:$Z$15,$AD13,0)} -> 4.33 | AI13: {=INDEX($Z$11:$Z$15,$AE13,0)} -> 6.2 | AJ13: =IF(AC13<>$Y$15, FORECAST(AC13,AH13:AI13,AF13:AG13),AH13) -> 4.3657044
A14: ='FL6 data'!C15*0.3048 -> 273.17395 | B14: =AJ14 -> 4.3714912 | C14: 4.2 | D14: 4.2 | E14: 4.2 | F14: 148.9 | G14: =('FL6 data'!D15-32)*5/9 -> 87.075559 | H14: =('FL6 data'!J15-32)*5/9 -> 53.406259 | I14: =('FL6 data'!P15-32)*5/9 -> 36.47261 | J14: =('FL6 data'!V15-32)*5/9 -> 70.787619 | K14: =('FL6 data'!AA15-32)*5/9 -> 43.04704 | L14: =('FL6 data'!AF15-32)*5/9 -> 28.8875 | M14: =('FL6 data'!AL15-32)*5/9 -> 57.359779 | N14: =('FL6 data'!AS15-32)*5/9 -> 35.22931 | O14: =('FL6 data'!AZ15-32)*5/9 -> 23.88028 | P14: =('FL6 data'!BN17-32)*5/9 -> 4.9502448 | Q14: =P14 -> 4.9502448 | S14: =A14*3.281 -> 896.28374 | T14: =$S$440-S14 -> -896.28374 | U14: =G14 -> 87.075559 | V14: =Pressure!K14 -> 160.60818 | Y14: =Y5 -> 13375.893 | Z14: =Z5 -> 13.5 | AC14: 273.17395 | AD14: =MATCH(AC14,$Y$11:$Y$15,1) -> 1 | AE14: =AD14+1 -> 2 | AF14: {=INDEX($Y$11:$Y$15,$AD14,0)} -> 0 | AG14: {=INDEX($Y$11:$Y$15,$AE14,0)} -> 12311.893 | AH14: {=INDEX($Z$11:$Z$15,$AD14,0)} -> 4.33 | AI14: {=INDEX($Z$11:$Z$15,$AE14,0)} -> 6.2 | AJ14: =IF(AC14<>$Y$15, FORECAST(AC14,AH14:AI14,AF14:AG14),AH14) -> 4.3714912
A15: ='FL6 data'!C16*0.3048 -> 311.27395 | B15: =AJ15 -> 4.3772781 | C15: 4.2 | D15: 4.2 | E15: 4.2 | F15: 148.9 | G15: =('FL6 data'!D16-32)*5/9 -> 86.981679 | H15: =('FL6 data'!J16-32)*5/9 -> 53.271499 | I15: =('FL6 data'!P16-32)*5/9 -> 36.08134 | J15: =('FL6 data'!V16-32)*5/9 -> 70.714789 | K15: =('FL6 data'!AA16-32)*5/9 -> 42.94223 | L15: =('FL6 data'!AF16-32)*5/9 -> 28.60923 | M15: =('FL6 data'!AL16-32)*5/9 -> 57.303989 | N15: =('FL6 data'!AS16-32)*5/9 -> 35.14986 | O15: =('FL6 data'!AZ16-32)*5/9 -> 23.66173 | P15: =('FL6 data'!BN18-32)*5/9 -> 4.9475418 | Q15: =P15 -> 4.9475418 | S15: =A15*3.281 -> 1021.2898 | T15: =$S$440-S15 -> -1021.2898 | U15: =G15 -> 86.981679 | V15: =Pressure!K15 -> 160.67508 | Y15: =Y4 -> 13575.893 | Z15: =Z4 -> 22.6 | AA15: =Y15/Y22/60+6.5 -> 36.66865 | AB15: 4.33 | AC15: 311.27395 | AD15: =MATCH(AC15,$Y$11:$Y$15,1) -> 1 | AE15: =AD15+1 -> 2 | AF15: {=INDEX($Y$11:$Y$15,$AD15,0)} -> 0 | AG15: {=INDEX($Y$11:$Y$15,$AE15,0)} -> 12311.893 | AH15: {=INDEX($Z$11:$Z$15,$AD15,0)} -> 4.33 | AI15: {=INDEX($Z$11:$Z$15,$AE15,0)} -> 6.2 | AJ15: =IF(AC15<>$Y$15, FORECAST(AC15,AH15:AI15,AF15:AG15),AH15) -> 4.3772781
A16: ='FL6 data'!C17*0.3048 -> 349.37395 | B16: =AJ16 -> 4.3830649 | C16: 4.2 | D16: 4.2 | E16: 4.2 | F16: 148.9 | G16: =('FL6 data'!D17-32)*5/9 -> 86.888969 | H16: =('FL6 data'!J17-32)*5/9 -> 53.137739 | I16: =('FL6 data'!P17-32)*5/9 -> 35.69667 | J16: =('FL6 data'!V17-32)*5/9 -> 70.636389 | K16: =('FL6 data'!AA17-32)*5/9 -> 42.82689 | L16: =('FL6 data'!AF17-32)*5/9 -> 28.31943 | M16: =('FL6 data'!AL17-32)*5/9 -> 57.236629 | N16: =('FL6 data'!AS17-32)*5/9 -> 35.05198 | O16: =('FL6 data'!AZ17-32)*5/9 -> 23.4246 | P16: =('FL6 data'!BN19-32)*5/9 -> 4.9446228 | Q16: =P16 -> 4.9446228 | S16: =A16*3.281 -> 1146.2959 | T16: =$S$440-S16 -> -1146.2959 | U16: =G16 -> 86.888969 | V16: =Pressure!K16 -> 160.79608 | AC16: 349.37395 | AD16: =MATCH(AC16,$Y$11:$Y$15,1) -> 1 | AE16: =AD16+1 -> 2 | AF16: {=INDEX($Y$11:$Y$15,$AD16,0)} -> 0 | AG16: {=INDEX($Y$11:$Y$15,$AE16,0)} -> 12311.893 | AH16: {=INDEX($Z$11:$Z$15,$AD16,0)} -> 4.33 | AI16: {=INDEX($Z$11:$Z$15,$AE16,0)} -> 6.2 | AJ16: =IF(AC16<>$Y$15, FORECAST(AC16,AH16:AI16,AF16:AG16),AH16) -> 4.3830649
A17: ='FL6 data'!C18*0.3048 -> 387.47395 | B17: =AJ17 -> 4.3888517 | C17: 4.2 | D17: 4.2 | E17: 4.2 | F17: 148.9 | G17: =('FL6 data'!D18-32)*5/9 -> 86.797439 | H17: =('FL6 data'!J18-32)*5/9 -> 53.005089 | I17: =('FL6 data'!P18-32)*5/9 -> 35.31931 | J17: =('FL6 data'!V18-32)*5/9 -> 70.563539 | K17: =('FL6 data'!AA18-32)*5/9 -> 42.725 | L17: =('FL6 data'!AF18-32)*5/9 -> 28.04707 | M17: =('FL6 data'!AL18-32)*5/9 -> 57.177109 | N17: =('FL6 data'!AS18-32)*5/9 -> 34.97255 | O17: =('FL6 data'!AZ18-32)*5/9 -> 23.20623 | P17: =('FL6 data'!BN20-32)*5/9 -> 4.9426978 | Q17: =P17 -> 4.9426978 | S17: =A17*3.281 -> 1271.302 | T17: =$S$440-S17 -> -1271.302 | U17: =G17 -> 86.797439 | V17: =Pressure!K17 -> 160.97118 | AC17: 387.47395 | AD17: =MATCH(AC17,$Y$11:$Y$15,1) -> 1 | AE17: =AD17+1 -> 2 | AF17: {=INDEX($Y$11:$Y$15,$AD17,0)} -> 0 | AG17: {=INDEX($Y$11:$Y$15,$AE17,0)} -> 12311.893 | AH17: {=INDEX($Z$11:$Z$15,$AD17,0)} -> 4.33 | AI17: {=INDEX($Z$11:$Z$15,$AE17,0)} -> 6.2 | AJ17: =IF(AC17<>$Y$15, FORECAST(AC17,AH17:AI17,AF17:AG17),AH17) -> 4.3888517
A18: ='FL6 data'!C19*0.3048 -> 425.57395 | B18: =AJ18 -> 4.3946386 | C18: 4.2 | D18: 4.2 | E18: 4.2 | F18: 148.9 | G18: =('FL6 data'!D19-32)*5/9 -> 86.705619 | H18: =('FL6 data'!J19-32)*5/9 -> 52.872509 | I18: =('FL6 data'!P19-32)*5/9 -> 34.94815 | J18: =('FL6 data'!V19-32)*5/9 -> 70.489849 | K18: =('FL6 data'!AA19-32)*5/9 -> 42.71669 | L18: =('FL6 data'!AF19-32)*5/9 -> 27.79082 | M18: =('FL6 data'!AL19-32)*5/9 -> 57.119409 | N18: =('FL6 data'!AS19-32)*5/9 -> 35.2476 | O18: =('FL6 data'!AZ19-32)*5/9 -> 23.02699 | P18: =('FL6 data'!BN21-32)*5/9 -> 4.9449958 | Q18: =P18 -> 4.9449958 | S18: =A18*3.281 -> 1396.3081 | T18: =$S$440-S18 -> -1396.3081 | U18: =G18 -> 86.705619 | V18: =Pressure!K18 -> 161.12668 | X18: length(m) | Y18: Duration (hr) | AC18: 425.57395 | AD18: =MATCH(AC18,$Y$11:$Y$15,1) -> 1 | AE18: =AD18+1 -> 2 | AF18: {=INDEX($Y$11:$Y$15,$AD18,0)} -> 0 | AG18: {=INDEX($Y$11:$Y$15,$AE18,0)} -> 12311.893 | AH18: {=INDEX($Z$11:$Z$15,$AD18,0)} -> 4.33 | AI18: {=INDEX($Z$11:$Z$15,$AE18,0)} -> 6.2 | AJ18: =IF(AC18<>$Y$15, FORECAST(AC18,AH18:AI18,AF18:AG18),AH18) -> 4.3946386
A19: ='FL6 data'!C20*0.3048 -> 463.67395 | B19: =AJ19 -> 4.4004254 | C19: 4.2 | D19: 4.2 | E19: 4.2 | F19: 148.9 | G19: =('FL6 data'!D20-32)*5/9 -> 86.613519 | H19: =('FL6 data'!J20-32)*5/9 -> 52.739999 | I19: =('FL6 data'!P20-32)*5/9 -> 34.58179 | J19: =('FL6 data'!V20-32)*5/9 -> 70.548119 | K19: =('FL6 data'!AA20-32)*5/9 -> 44.73244 | L19: =('FL6 data'!AF20-32)*5/9 -> 28.83018 | M19: =('FL6 data'!AL20-32)*5/9 -> 57.158849 | N19: =('FL6 data'!AS20-32)*5/9 -> 38.49628 | O19: =('FL6 data'!AZ20-32)*5/9 -> 24.96598 | P19: =('FL6 data'!BN22-32)*5/9 -> 4.9604738 | Q19: =P19 -> 4.9604738 | S19: =A19*3.281 -> 1521.3142 | T19: =$S$440-S19 -> -1521.3142 | U19: =G19 -> 86.613519 | V19: =Pressure!K19 -> 161.26248 | Y19: 6.5 | Z19: 6.2 | AC19: 463.67395 | AD19: =MATCH(AC19,$Y$11:$Y$15,1) -> 1 | AE19: =AD19+1 -> 2 | AF19: {=INDEX($Y$11:$Y$15,$AD19,0)} -> 0 | AG19: {=INDEX($Y$11:$Y$15,$AE19,0)} -> 12311.893 | AH19: {=INDEX($Z$11:$Z$15,$AD19,0)} -> 4.33 | AI19: {=INDEX($Z$11:$Z$15,$AE19,0)} -> 6.2 | AJ19: =IF(AC19<>$Y$15, FORECAST(AC19,AH19:AI19,AF19:AG19),AH19) -> 4.4004254
A20: ='FL6 data'!C21*0.3048 -> 497.73535 | B20: =AJ20 -> 4.4055989 | C20: 4.2 | D20: 4.2 | E20: 4.2 | F20: 148.9 | G20: =('FL6 data'!D21-32)*5/9 -> 86.540079 | H20: =('FL6 data'!J21-32)*5/9 -> 52.634969 | I20: =('FL6 data'!P21-32)*5/9 -> 34.29511 | J20: =('FL6 data'!V21-32)*5/9 -> 70.462769 | K20: =('FL6 data'!AA21-32)*5/9 -> 44.71542 | L20: =('FL6 data'!AF21-32)*5/9 -> 28.86227 | M20: =('FL6 data'!AL21-32)*5/9 -> 57.358019 | N20: =('FL6 data'!AS21-32)*5/9 -> 38.46371 | O20: =('FL6 data'!AZ21-32)*5/9 -> 25.06153 | P20: =('FL6 data'!BN23-32)*5/9 -> 4.9969418 | Q20: =P20 -> 4.9969418 | S20: =A20*3.281 -> 1633.0697 | T20: =$S$440-S20 -> -1633.0697 | U20: =G20 -> 86.540079 | V20: =Pressure!K20 -> 161.30689 | X20: =(72-6.5)*Y22*60 -> 29475 | Y20: 72 | Z20: 4.2 | AC20: 497.73535 | AD20: =MATCH(AC20,$Y$11:$Y$15,1) -> 1 | AE20: =AD20+1 -> 2 | AF20: {=INDEX($Y$11:$Y$15,$AD20,0)} -> 0 | AG20: {=INDEX($Y$11:$Y$15,$AE20,0)} -> 12311.893 | AH20: {=INDEX($Z$11:$Z$15,$AD20,0)} -> 4.33 | AI20: {=INDEX($Z$11:$Z$15,$AE20,0)} -> 6.2 | AJ20: =IF(AC20<>$Y$15, FORECAST(AC20,AH20:AI20,AF20:AG20),AH20) -> 4.4055989
A21: ='FL6 data'!C22*0.3048 -> 527.75815 | B21: =AJ21 -> 4.4101589 | C21: 4.2 | D21: 4.2 | E21: 4.2 | F21: 148.9 | G21: =('FL6 data'!D22-32)*5/9 -> 86.464599 | H21: =('FL6 data'!J22-32)*5/9 -> 52.528569 | I21: =('FL6 data'!P22-32)*5/9 -> 34.00925 | J21: =('FL6 data'!V22-32)*5/9 -> 70.300919 | K21: =('FL6 data'!AA22-32)*5/9 -> 44.56472 | L21: =('FL6 data'!AF22-32)*5/9 -> 28.58415 | M21: =('FL6 data'!AL22-32)*5/9 -> 56.964379 | N21: =('FL6 data'!AS22-32)*5/9 -> 38.33572 | O21: =('FL6 data'!AZ22-32)*5/9 -> 24.81545 | P21: =('FL6 data'!BN24-32)*5/9 -> 4.9521398 | Q21: =P21 -> 4.9521398 | S21: =A21*3.281 -> 1731.5745 | T21: =$S$440-S21 -> -1731.5745 | U21: =G21 -> 86.464599 | V21: =Pressure!K21 -> 161.25988 | Y21: layspeed | AC21: 527.75815 | AD21: =MATCH(AC21,$Y$11:$Y$15,1) -> 1 | AE21: =AD21+1 -> 2 | AF21: {=INDEX($Y$11:$Y$15,$AD21,0)} -> 0 | AG21: {=INDEX($Y$11:$Y$15,$AE21,0)} -> 12311.893 | AH21: {=INDEX($Z$11:$Z$15,$AD21,0)} -> 4.33 | AI21: {=INDEX($Z$11:$Z$15,$AE21,0)} -> 6.2 | AJ21: =IF(AC21<>$Y$15, FORECAST(AC21,AH21:AI21,AF21:AG21),AH21) -> 4.4101589
A22: ='FL6 data'!C23*0.3048 -> 554.12564 | B22: =AJ22 -> 4.4141637 | C22: 4.2 | D22: 4.2 | E22: 4.2 | F22: 148.9 | G22: =('FL6 data'!D23-32)*5/9 -> 86.407399 | H22: =('FL6 data'!J23-32)*5/9 -> 52.448009 | I22: =('FL6 data'!P23-32)*5/9 -> 33.79358 | J22: =('FL6 data'!V23-32)*5/9 -> 70.248879 | K22: =('FL6 data'!AA23-32)*5/9 -> 44.51673 | L22: =('FL6 data'!AF23-32)*5/9 -> 28.47506 | M22: =('FL6 data'!AL23-32)*5/9 -> 56.922939 | N22: =('FL6 data'!AS23-32)*5/9 -> 38.30078 | O22: =('FL6 data'!AZ23-32)*5/9 -> 24.72687 | P22: =('FL6 data'!BN25-32)*5/9 -> 4.9391588 | Q22: =P22 -> 4.9391588 | S22: =A22*3.281 -> 1818.0862 | T22: =$S$440-S22 -> -1818.0862 | U22: =G22 -> 86.407399 | V22: =Pressure!K22 -> 161.20288 | Y22: 7.5 | Z22: m/min | AC22: 554.12564 | AD22: =MATCH(AC22,$Y$11:$Y$15,1) -> 1 | AE22: =AD22+1 -> 2 | AF22: {=INDEX($Y$11:$Y$15,$AD22,0)} -> 0 | AG22: {=INDEX($Y$11:$Y$15,$AE22,0)} -> 12311.893 | AH22: {=INDEX($Z$11:$Z$15,$AD22,0)} -> 4.33 | AI22: {=INDEX($Z$11:$Z$15,$AE22,0)} -> 6.2 | AJ22: =IF(AC22<>$Y$15, FORECAST(AC22,AH22:AI22,AF22:AG22),AH22) -> 4.4141637
A23: ='FL6 data'!C24*0.3048 -> 576.83781 | B23: =AJ23 -> 4.4176134 | C23: 4.2 | D23: 4.2 | E23: 4.2 | F23: 148.9 | G23: =('FL6 data'!D24-32)*5/9 -> 86.349759 | H23: =('FL6 data'!J24-32)*5/9 -> 52.367409 | I23: =('FL6 data'!P24-32)*5/9 -> 33.57949 | J23: =('FL6 data'!V24-32)*5/9 -> 70.202249 | K23: =('FL6 data'!AA24-32)*5/9 -> 44.40281 | L23: =('FL6 data'!AF24-32)*5/9 -> 28.29444 | M23: =('FL6 data'!AL24-32)*5/9 -> 56.885499 | N23: =('FL6 data'!AS24-32)*5/9 -> 38.16087 | O23: =('FL6 data'!AZ24-32)*5/9 -> 24.57473 | P23: =('FL6 data'!BN26-32)*5/9 -> 4.9339988 | Q23: =P23 -> 4.9339988 | S23: =A23*3.281 -> 1892.6049 | T23: =$S$440-S23 -> -1892.6049 | U23: =G23 -> 86.349759 | V23: =Pressure!K23 -> 161.13588 | AC23: 576.83781 | AD23: =MATCH(AC23,$Y$11:$Y$15,1) -> 1 | AE23: =AD23+1 -> 2 | AF23: {=INDEX($Y$11:$Y$15,$AD23,0)} -> 0 | AG23: {=INDEX($Y$11:$Y$15,$AE23,0)} -> 12311.893 | AH23: {=INDEX($Z$11:$Z$15,$AD23,0)} -> 4.33 | AI23: {=INDEX($Z$11:$Z$15,$AE23,0)} -> 6.2 | AJ23: =IF(AC23<>$Y$15, FORECAST(AC23,AH23:AI23,AF23:AG23),AH23) -> 4.4176134
A24: ='FL6 data'!C25*0.3048 -> 599.55074 | B24: =AJ24 -> 4.4210632 | C24: 4.2 | D24: 4.2 | E24: 4.2 | F24: 148.9 | G24: =('FL6 data'!D25-32)*5/9 -> 86.292099 | H24: =('FL6 data'!J25-32)*5/9 -> 52.286909 | I24: =('FL6 data'!P25-32)*5/9 -> 33.3675 | J24: =('FL6 data'!V25-32)*5/9 -> 70.155539 | K24: =('FL6 data'!AA25-32)*5/9 -> 43.92347 | L24: =('FL6 data'!AF25-32)*5/9 -> 28.11297 | M24: =('FL6 data'!AL25-32)*5/9 -> 56.848099 | N24: =('FL6 data'!AS25-32)*5/9 -> 36.99143 | O24: =('FL6 data'!AZ25-32)*5/9 -> 24.42135 | P24: =('FL6 data'!BN27-32)*5/9 -> 4.9321428 | Q24: =P24 -> 4.9321428 | S24: =A24*3.281 -> 1967.126 | T24: =$S$440-S24 -> -1967.126 | U24: =G24 -> 86.292099 | V24: =Pressure!K24 -> 161.06598 | AC24: 599.55074 | AD24: =MATCH(AC24,$Y$11:$Y$15,1) -> 1 | AE24: =AD24+1 -> 2 | AF24: {=INDEX($Y$11:$Y$15,$AD24,0)} -> 0 | AG24: {=INDEX($Y$11:$Y$15,$AE24,0)} -> 12311.893 | AH24: {=INDEX($Z$11:$Z$15,$AD24,0)} -> 4.33 | AI24: {=INDEX($Z$11:$Z$15,$AE24,0)} -> 6.2 | AJ24: =IF(AC24<>$Y$15, FORECAST(AC24,AH24:AI24,AF24:AG24),AH24) -> 4.4210632

Sheet Pressure
A1: Profile Name | B1: Install | C1: External Pressure | D1: Flooded | E1: LeakTest | F1: Hydrotest | G1: Remove_hydro | H1: Dewater | I1: FillContent | J1: Design | K1: OPSS_Early | L1: OPSS_Mid | M1: OPSS_Lat | N1: PCD_Early | O1: PCD_Mid | P1: PCD_Lat | Q1: HCD_Early | R1: HCD_Mid | S1: HCD_Lat | T1: FCD_Early | U1: FCD_Mid
A2: KP | B2: Pressure | C2: Pressure | D2: Pressure | E2: Pressure | F2: Pressure | G2: Pressure | H2: Pressure | I2: Pressure | J2: Pressure | K2: Pressure | L2: Pressure | M2: Pressure | N2: Pressure | O2: Pressure | P2: Pressure | Q2: Pressure | R2: Pressure | S2: Pressure | T2: Pressure | U2: Pressure
A3: [m] | B3: [Bar] | C3: [Bar] | D3: [Bar] | E3: [Bar] | F3: [Bar] | G3: [Bar] | H3: [Bar] | I3: [Bar] | J3: [Bar] | K3: [Bar] | L3: [Bar] | M3: [Bar] | N3: [Bar] | O3: [Bar] | P3: [Bar] | Q3: [Bar] | R3: [Bar] | S3: [Bar] | T3: [Bar] | U3: [Bar]
A4: 0 | B4: 1 | C4: =FL6_WD!U3 -> 121.26592 | D4: =FL6_WD!V3 -> 120.67438 | E4: =FL6_WD!W3 -> 1351.2809 | F4: =FL6_WD!X3 -> 1519.0059 | G4: =FL6_WD!Y3 -> 120.67438 | H4: 1 | I4: =FL6_WD!Z3 -> 108.9737 | J4: =FL6_WD!AA3 -> 1217.5359 | K4: =K5 -> 160.39218 | L4: =L5 -> 148.76961 | M4: =M5 -> 157.56686 | N4: =N5 -> 147.9637 | O4: =O5 -> 142.83957 | P4: =P5 -> 151.53413 | Q4: =Q5 -> 129.73329 | R4: =R5 -> 142.91217 | ... T4: =T5 -> 82.132182 | U4: =T4 -> 82.132182
A5: 14.795924 | B5: 1 | C5: =FL6_WD!U4 -> 121.26709 | D5: =FL6_WD!V4 -> 120.67554 | E5: =FL6_WD!W4 -> 1351.2821 | F5: =FL6_WD!X4 -> 1519.0071 | G5: =FL6_WD!Y4 -> 120.67554 | H5: 1 | I5: =FL6_WD!Z4 -> 108.97475 | J5: =FL6_WD!AA4 -> 1217.5371 | K5: ='FL6 data'!E6*0.068948 -> 160.39218 | L5: ='FL6 data'!K6*0.068948 -> 148.76961 | M5: ='FL6 data'!Q6*0.068948 -> 157.56686 | N5: ='FL6 data'!W6*0.068948 -> 147.9637 | O5: ='FL6 data'!AB6*0.068948 -> 142.83957 | P5: ='FL6 data'!AG6*0.068948 -> 151.53413 | Q5: ='FL6 data'!AN6*0.068948 -> 129.73329 | R5: ='FL6 data'!AU6*0.068948 -> 142.91217 | S5: ='FL6 data'!BB6*0.068948 -> 147.5849 | T5: ='FL6 data'!BK8*0.068948 -> 82.132182 | U5: =T5 -> 82.132182
A6: 44.387772 | B6: 1 | C6: =FL6_WD!U5 -> 121.2506 | D6: =FL6_WD!V5 -> 120.65913 | E6: =FL6_WD!W5 -> 1351.2656 | F6: =FL6_WD!X5 -> 1518.9906 | G6: =FL6_WD!Y5 -> 120.65913 | H6: 1 | I6: =FL6_WD!Z5 -> 108.95992 | J6: =FL6_WD!AA5 -> 1217.5206 | K6: ='FL6 data'!E7*0.068948 -> 160.46988 | L6: ='FL6 data'!K7*0.068948 -> 148.88921 | M6: ='FL6 data'!Q7*0.068948 -> 157.69256 | N6: ='FL6 data'!W7*0.068948 -> 148.0855 | O6: ='FL6 data'!AB7*0.068948 -> 142.96397 | P6: ='FL6 data'!AG7*0.068948 -> 151.66003 | Q6: ='FL6 data'!AN7*0.068948 -> 129.85599 | R6: ='FL6 data'!AU7*0.068948 -> 143.03737 | S6: ='FL6 data'!BB7*0.068948 -> 147.7112 | T6: ='FL6 data'!BK9*0.068948 -> 82.205312 | U6: =T6 -> 82.205312
A7: 67.691848 | B7: 1 | C7: =FL6_WD!U6 -> 121.25706 | D7: =FL6_WD!V6 -> 120.66556 | E7: =FL6_WD!W6 -> 1351.2721 | F7: =FL6_WD!X6 -> 1518.9971 | G7: =FL6_WD!Y6 -> 120.66556 | H7: 1 | I7: =FL6_WD!Z6 -> 108.96573 | J7: =FL6_WD!AA6 -> 1217.5271 | K7: ='FL6 data'!E8*0.068948 -> 160.53098 | L7: ='FL6 data'!K8*0.068948 -> 148.98341 | M7: ='FL6 data'!Q8*0.068948 -> 157.79156 | N7: ='FL6 data'!W8*0.068948 -> 148.18151 | O7: ='FL6 data'!AB8*0.068948 -> 143.06207 | P7: ='FL6 data'!AG8*0.068948 -> 151.75913 | Q7: ='FL6 data'!AN8*0.068948 -> 129.95269 | R7: ='FL6 data'!AU8*0.068948 -> 143.13597 | S7: ='FL6 data'!BB8*0.068948 -> 147.8106 | T7: ='FL6 data'!BK10*0.068948 -> 82.304373 | U7: =T7 -> 82.304373
A8: 82.580988 | B8: 1 | C8: =FL6_WD!U7 -> 121.26253 | D8: =FL6_WD!V7 -> 120.671 | E8: =FL6_WD!W7 -> 1351.2775 | F8: =FL6_WD!X7 -> 1519.0025 | G8: =FL6_WD!Y7 -> 120.671 | H8: 1 | I8: =FL6_WD!Z7 -> 108.97065 | J8: =FL6_WD!AA7 -> 1217.5325 | K8: ='FL6 data'!E9*0.068948 -> 160.54718 | L8: ='FL6 data'!K9*0.068948 -> 149.01941 | M8: ='FL6 data'!Q9*0.068948 -> 157.83056 | N8: ='FL6 data'!W9*0.068948 -> 148.21971 | O8: ='FL6 data'!AB9*0.068948 -> 143.10107 | P8: ='FL6 data'!AG9*0.068948 -> 151.79863 | Q8: ='FL6 data'!AN9*0.068948 -> 129.99119 | R8: ='FL6 data'!AU9*0.068948 -> 143.17527 | S8: ='FL6 data'!BB9*0.068948 -> 147.8502 | T8: ='FL6 data'!BK11*0.068948 -> 82.343983 | U8: =T8 -> 82.343983
A9: 95.342964 | B9: 1 | C9: =FL6_WD!U8 -> 121.27591 | D9: =FL6_WD!V8 -> 120.68432 | E9: =FL6_WD!W8 -> 1351.2909 | F9: =FL6_WD!X8 -> 1519.0159 | G9: =FL6_WD!Y8 -> 120.68432 | H9: 1 | I9: =FL6_WD!Z8 -> 108.98268 | J9: =FL6_WD!AA8 -> 1217.5459 | K9: ='FL6 data'!E10*0.068948 -> 160.53488 | L9: ='FL6 data'!K10*0.068948 -> 149.02361 | M9: ='FL6 data'!Q10*0.068948 -> 157.83716 | N9: ='FL6 data'!W10*0.068948 -> 148.22601 | O9: ='FL6 data'!AB10*0.068948 -> 143.10757 | P9: ='FL6 data'!AG10*0.068948 -> 151.80513 | Q9: ='FL6 data'!AN10*0.068948 -> 129.99759 | R9: ='FL6 data'!AU10*0.068948 -> 143.18177 | S9: ='FL6 data'!BB10*0.068948 -> 147.8568 | T9: ='FL6 data'!BK12*0.068948 -> 82.350433 | U9: =T9 -> 82.350433
A10: 114.44935 | B10: 1 | C10: =FL6_WD!U9 -> 121.29662 | D10: =FL6_WD!V9 -> 120.70493 | E10: =FL6_WD!W9 -> 1351.3116 | F10: =FL6_WD!X9 -> 1519.0366 | G10: =FL6_WD!Y9 -> 120.70493 | H10: 1 | I10: =FL6_WD!Z9 -> 109.00128 | J10: =FL6_WD!AA9 -> 1217.5666 | K10: ='FL6 data'!E11*0.068948 -> 160.54108 | L10: ='FL6 data'!K11*0.068948 -> 149.05581 | M10: ='FL6 data'!Q11*0.068948 -> 157.87286 | N10: ='FL6 data'!W11*0.068948 -> 148.26041 | O10: ='FL6 data'!AB11*0.068948 -> 143.14307 | P10: ='FL6 data'!AG11*0.068948 -> 151.84113 | Q10: ='FL6 data'!AN11*0.068948 -> 130.03219 | R10: ='FL6 data'!AU11*0.068948 -> 143.21757 | S10: ='FL6 data'!BB11*0.068948 -> 147.8929 | T10: ='FL6 data'!BK13*0.068948 -> 82.386023 | U10: =T10 -> 82.386023
A11: 152.54935 | B11: 1 | C11: =FL6_WD!U10 -> 121.29503 | D11: =FL6_WD!V10 -> 120.70335 | E11: =FL6_WD!W10 -> 1351.31 | F11: =FL6_WD!X10 -> 1519.035 | G11: =FL6_WD!Y10 -> 120.70335 | H11: 1 | I11: =FL6_WD!Z10 -> 108.99985 | J11: =FL6_WD!AA10 -> 1217.565 | K11: ='FL6 data'!E12*0.068948 -> 160.57818 | L11: ='FL6 data'!K12*0.068948 -> 149.14471 | M11: ='FL6 data'!Q12*0.068948 -> 157.96916 | N11: ='FL6 data'!W12*0.068948 -> 148.35381 | O11: ='FL6 data'!AB12*0.068948 -> 143.23847 | P11: ='FL6 data'!AG12*0.068948 -> 151.93763 | Q11: ='FL6 data'!AN12*0.068948 -> 130.12629 | R11: ='FL6 data'!AU12*0.068948 -> 143.31358 | S11: ='FL6 data'!BB12*0.068948 -> 147.9897 | T11: ='FL6 data'!BK14*0.068948 -> 82.482824 | U11: =T11 -> 82.482824
A12: 196.97395 | B12: 1 | C12: =FL6_WD!U11 -> 121.37216 | D12: =FL6_WD!V11 -> 120.7801 | E12: =FL6_WD!W11 -> 1351.3872 | F12: =FL6_WD!X11 -> 1519.1122 | G12: =FL6_WD!Y11 -> 120.7801 | H12: 1 | I12: =FL6_WD!Z11 -> 109.06917 | J12: =FL6_WD!AA11 -> 1217.6422 | K12: ='FL6 data'!E13*0.068948 -> 160.59588 | L12: ='FL6 data'!K13*0.068948 -> 149.22131 | M12: ='FL6 data'!Q13*0.068948 -> 158.05457 | N12: ='FL6 data'!W13*0.068948 -> 148.43691 | O12: ='FL6 data'!AB13*0.068948 -> 143.32338 | P12: ='FL6 data'!AG13*0.068948 -> 152.02353 | Q12: ='FL6 data'!AN13*0.068948 -> 130.21 | R12: ='FL6 data'!AU13*0.068948 -> 143.39888 | S12: ='FL6 data'!BB13*0.068948 -> 148.0759 | T12: ='FL6 data'!BK15*0.068948 -> 82.568794 | U12: =T12 -> 82.568794
A13: 235.07395 | B13: 1 | C13: =FL6_WD!U12 -> 121.44472 | D13: =FL6_WD!V12 -> 120.85231 | E13: =FL6_WD!W12 -> 1351.4597 | F13: =FL6_WD!X12 -> 1519.1847 | G13: =FL6_WD!Y12 -> 120.85231 | H13: 1 | I13: =FL6_WD!Z12 -> 109.13437 | J13: =FL6_WD!AA12 -> 1217.7147 | K13: ='FL6 data'!E14*0.068948 -> 160.58188 | L13: ='FL6 data'!K14*0.068948 -> 149.25701 | M13: ='FL6 data'!Q14*0.068948 -> 158.09757 | N13: ='FL6 data'!W14*0.068948 -> 148.47861 | O13: ='FL6 data'!AB14*0.068948 -> 143.36608 | P13: ='FL6 data'!AG14*0.068948 -> 152.06663 | Q13: ='FL6 data'!AN14*0.068948 -> 130.252 | R13: ='FL6 data'!AU14*0.068948 -> 143.44178 | S13: ='FL6 data'!BB14*0.068948 -> 148.1191 | T13: ='FL6 data'!BK16*0.068948 -> 82.611805 | U13: =T13 -> 82.611805
A14: 273.17395 | B14: 1 | C14: =FL6_WD!U13 -> 121.49524 | D14: =FL6_WD!V13 -> 120.90258 | E14: =FL6_WD!W13 -> 1351.5102 | F14: =FL6_WD!X13 -> 1519.2352 | G14: =FL6_WD!Y13 -> 120.90258 | H14: 1 | I14: =FL6_WD!Z13 -> 109.17977 | J14: =FL6_WD!AA13 -> 1217.7652 | K14: ='FL6 data'!E15*0.068948 -> 160.60818 | L14: ='FL6 data'!K15*0.068948 -> 149.33531 | M14: ='FL6 data'!Q15*0.068948 -> 158.18327 | N14: ='FL6 data'!W15*0.068948 -> 148.56121 | O14: ='FL6 data'!AB15*0.068948 -> 143.45048 | P14: ='FL6 data'!AG15*0.068948 -> 152.15203 | Q14: ='FL6 data'!AN15*0.068948 -> 130.3352 | R14: ='FL6 data'!AU15*0.068948 -> 143.52678 | S14: ='FL6 data'!BB15*0.068948 -> 148.20481 | T14: ='FL6 data'!BK17*0.068948 -> 82.697335 | U14: =T14 -> 82.697335
A15: 311.27395 | B15: 1 | C15: =FL6_WD!U14 -> 121.5273 | D15: =FL6_WD!V14 -> 120.93448 | E15: =FL6_WD!W14 -> 1351.5423 | F15: =FL6_WD!X14 -> 1519.2673 | G15: =FL6_WD!Y14 -> 120.93448 | H15: 1 | I15: =FL6_WD!Z14 -> 109.20858 | J15: =FL6_WD!AA14 -> 1217.7973 | K15: ='FL6 data'!E16*0.068948 -> 160.67508 | L15: ='FL6 data'!K16*0.068948 -> 149.45471 | M15: ='FL6 data'!Q16*0.068948 -> 158.31067 | N15: ='FL6 data'!W16*0.068948 -> 148.68471 | O15: ='FL6 data'!AB16*0.068948 -> 143.57668 | P15: ='FL6 data'!AG16*0.068948 -> 152.27973 | Q15: ='FL6 data'!AN16*0.068948 -> 130.4595 | R15: ='FL6 data'!AU16*0.068948 -> 143.65368 | S15: ='FL6 data'!BB16*0.068948 -> 148.33281 | T15: ='FL6 data'!BK18*0.068948 -> 82.825346 | U15: =T15 -> 82.825346
A16: 349.37395 | B16: 1 | C16: =FL6_WD!U15 -> 121.56816 | D16: =FL6_WD!V15 -> 120.97515 | E16: =FL6_WD!W15 -> 1351.5832 | F16: =FL6_WD!X15 -> 1519.3082 | G16: =FL6_WD!Y15 -> 120.97515 | H16: 1 | I16: =FL6_WD!Z15 -> 109.2453 | J16: =FL6_WD!AA15 -> 1217.8382 | K16: ='FL6 data'!E17*0.068948 -> 160.79608 | L16: ='FL6 data'!K17*0.068948 -> 149.63071 | M16: ='FL6 data'!Q17*0.068948 -> 158.49527 | N16: ='FL6 data'!W17*0.068948 -> 148.86291 | O16: ='FL6 data'!AB17*0.068948 -> 143.75878 | P16: ='FL6 data'!AG17*0.068948 -> 152.46403 | Q16: ='FL6 data'!AN17*0.068948 -> 130.639 | R16: ='FL6 data'!AU17*0.068948 -> 143.83688 | S16: ='FL6 data'!BB17*0.068948 -> 148.51771 | T16: ='FL6 data'!BK19*0.068948 -> 83.010267 | U16: =T16 -> 83.010267
... A89: 2317.0469 | B89: 1 | C89: =FL6_WD!U88 -> 779.93108 | D89: =FL6_WD!V88 -> 776.12654 | E89: =FL6_WD!W88 -> 2009.9461 | F89: =FL6_WD!X88 -> 2177.6711 | G89: =FL6_WD!Y88 -> 776.12654 | H89: 1 | I89: =FL6_WD!Z88 -> 700.8727 | J89: =FL6_WD!AA88 -> 1876.2011 | K89: ='FL6 data'!E90*0.068948 -> 157.19196 | L89: ='FL6 data'!K90*0.068948 -> 148.26741 | M89: ='FL6 data'!Q90*0.068948 -> 157.13826 | N89: ='FL6 data'!W90*0.068948 -> 148.1105 | O89: ='FL6 data'!AB90*0.068948 -> 142.95107 | P89: ='FL6 data'!AG90*0.068948 -> 151.30522 | Q89: ='FL6 data'!AN90*0.068948 -> 129.88249 | R89: ='FL6 data'!AU90*0.068948 -> 143.03307 | S89: ='FL6 data'!BB90*0.068948 -> 147.374 | T89: ='FL6 data'!BK92*0.068948 -> 82.262892 | U89: =T89 -> 82.262892

Sheet FL6_WD
A1: KP(ft) | B1: WD (ft) | C1: KP(m) | D1: WD (m) | E1: ExternalPressure[bar] | F1: Flooded[Bar] | G1: Hydrotest[Bar] | H1: Remove_hydrotest[Bar] | I1: Dewater[Bar] | J1: Fill_Content | K1: Design_Pressure[Bar] | M1: KP | N1: WD_rowLB | O1: WD_rowUB | P1: KP_LB | Q1: KP_UB | R1: WD_LB | S1: WD_UB | T1: WD_PRE | U1: External Pressure | V1: Flooded | W1: LeakTest | X1: Hydrotest | Y1: RemoveHydro | Z1: Fill_Content | AA1: Design
A2: 0 | B2: -3956.68 | C2: =A2*0.3048 -> 0 | D2: =B2*0.3048 -> -1205.9961 | E2: =D2*-1*1025*9.81/10^5 -> 121.26592 | F2: =1020*D2*-1*9.81/10^5 -> 120.67438 | G2: =1397.74+E2 -> 1519.0059 | H2: =F2 -> 120.67438 | I2: 1 | J2: =921.1*D2*-1*9.81/10^5 -> 108.9737 | K2: =1096.27+E2 -> 1217.5359 | M2: [m] | N2: [-] | O2: [-] | P2: [m] | Q2: [m] | R2: [m] | S2: [m] | T2: [m] | U2: [bar] | V2: [bar] | W2: [bar] | X2: [bar] | Y2: [bar] | Z2: [bar] | AA2: [bar] | AC2: design= | AD2: 1096.27 | AE2: bar
A3: 3 | B3: -3956.68 | C3: =A3*0.3048 -> 0.9144 | D3: =B3*0.3048 -> -1205.9961 | E3: =D3*-1*1025*9.81/10^5 -> 121.26592 | F3: =1020*D3*-1*9.81/10^5 -> 120.67438 | G3: =1397.74+E3 -> 1519.0059 | H3: =F3 -> 120.67438 | I3: 1 | J3: =921.1*D3*-1*9.81/10^5 -> 108.9737 | K3: =1096.27+E3 -> 1217.5359 | M3: 0 | N3: =MATCH($M3,$C$2:$C$14395,1) -> 1 | O3: =N3+1 -> 2 | P3: {=INDEX($C$2:$C$14395,$N3,0)} -> 0 | Q3: {=INDEX($C$2:$C$14395,$O3,0)} -> 0.9144 | R3: {=INDEX($D$2:$D$14395,$N3,0)} -> -1205.9961 | S3: {=INDEX($D$2:$D$14395,$O3,0)} -> -1205.9961 | T3: =FORECAST(M3,R3:S3,P3:Q3) -> -1205.9961 | U3: =1025*T3*-1*9.81/10^5 -> 121.26592 | V3: =1020*T3*-1*9.81/10^5 -> 120.67438 | W3: =1230.015+U3 -> 1351.2809 | X3: =1397.74+U3 -> 1519.0059 | Y3: =V3 -> 120.67438 | Z3: =921.1*T3*-1*9.81/10^5 -> 108.9737 | AA3: =1096.27+U3 -> 1217.5359 | AC3: hdyrotest | AD3: =AD2*1.25*1.02 -> 1397.7443 | AE3: bar
A4: 6 | B4: -3956.69 | C4: =A4*0.3048 -> 1.8288 | D4: =B4*0.3048 -> -1205.9991 | E4: =D4*-1*1025*9.81/10^5 -> 121.26623 | F4: =1020*D4*-1*9.81/10^5 -> 120.67468 | G4: =1397.74+E4 -> 1519.0062 | H4: =F4 -> 120.67468 | I4: 1 | J4: =921.1*D4*-1*9.81/10^5 -> 108.97397 | K4: =1096.27+E4 -> 1217.5362 | M4: 14.795924 | N4: =MATCH($M4,$C$2:$C$14395,1) -> 17 | O4: =N4+1 -> 18 | P4: {=INDEX($C$2:$C$14395,$N4,0)} -> 14.6304 | Q4: {=INDEX($C$2:$C$14395,$O4,0)} -> 15.5448 | R4: {=INDEX($D$2:$D$14395,$N4,0)} -> -1206.0083 | S4: {=INDEX($D$2:$D$14395,$O4,0)} -> -1206.0052 | T4: =FORECAST(M4,R4:S4,P4:Q4) -> -1206.0077 | U4: =1025*T4*-1*9.81/10^5 -> 121.26709 | V4: =1020*T4*-1*9.81/10^5 -> 120.67554 | W4: =1230.015+U4 -> 1351.2821 | X4: =1397.74+U4 -> 1519.0071 | Y4: =V4 -> 120.67554 | Z4: =921.1*T4*-1*9.81/10^5 -> 108.97475 | AA4: =1096.27+U4 -> 1217.5371 | AC4: leaktest | AD4: =AD2*1.1*1.02 -> 1230.0149 | AE4: bar
